5:return {{["x"] = 0, ["y"] = 0, ["z"] = 1, ["name"] = "default:wood"}, {["x"] = 0, ["y"] = 0, ["z"] = 2, ["name"] = "default:wood"}, {["x"] = 0, ["y"] = 0, ["z"] = 3, ["name"] = "default:wood"}, {["x"] = 0, ["y"] = 0, ["z"] = 4, ["name"] = "default:wood"}, {["x"] = 0, ["y"] = 0, ["z"] = 12, ["name"] = "default:wood"}, {["x"] = 0, ["y"] = 0, ["z"] = 13, ["name"] = "default:wood"}, {["x"] = 0, ["y"] = 0, ["z"] = 14, ["name"] = "default:wood"}, {["x"] = 0, ["y"] = 0, ["z"] = 15, ["name"] = "default:wood"}, {["x"] = 1, ["y"] = 0, ["z"] = 1, ["name"] = "default:wood"}, {["x"] = 1, ["y"] = 0, ["z"] = 2, ["name"] = "default:wood"}, {["x"] = 1, ["y"] = 0, ["z"] = 3, ["name"] = "default:wood"}, {["x"] = 1, ["y"] = 0, ["z"] = 4, ["name"] = "default:wood"}, {["x"] = 1, ["y"] = 0, ["z"] = 12, ["name"] = "default:wood"}, {["x"] = 1, ["y"] = 0, ["z"] = 13, ["name"] = "default:wood"}, {["x"] = 1, ["y"] = 0, ["z"] = 14, ["name"] = "default:wood"}, {["x"] = 1, ["y"] = 0, ["z"] = 15, ["name"] = "default:wood"}, {["x"] = 1, ["y"] = 1, ["z"] = 2, ["name"] = "default:wood"}, {["x"] = 1, ["y"] = 1, ["z"] = 3, ["name"] = "default:wood"}, {["x"] = 1, ["y"] = 1, ["z"] = 13, ["name"] = "default:wood"}, {["x"] = 1, ["y"] = 1, ["z"] = 14, ["name"] = "default:wood"}, {["x"] = 1, ["y"] = 2, ["z"] = 2, ["name"] = "default:wood"}, {["x"] = 1, ["y"] = 2, ["z"] = 3, ["name"] = "default:wood"}, {["x"] = 1, ["y"] = 2, ["z"] = 13, ["name"] = "default:wood"}, {["x"] = 1, ["y"] = 2, ["z"] = 14, ["name"] = "default:wood"}, {["x"] = 1, ["y"] = 3, ["z"] = 2, ["name"] = "default:wood"}, {["x"] = 1, ["y"] = 3, ["z"] = 3, ["name"] = "default:wood"}, {["x"] = 1, ["y"] = 3, ["z"] = 13, ["name"] = "default:wood"}, {["x"] = 1, ["y"] = 3, ["z"] = 14, ["name"] = "default:wood"}, {["x"] = 1, ["y"] = 4, ["z"] = 2, ["name"] = "default:wood"}, {["x"] = 1, ["y"] = 4, ["z"] = 3, ["name"] = "default:wood"}, {["x"] = 1, ["y"] = 4, ["z"] = 13, ["name"] = "default:wood"}, {["x"] = 1, ["y"] = 4, ["z"] = 14, ["name"] = "default:wood"}, {["x"] = 1, ["y"] = 5, ["z"] = 2, ["name"] = "default:wood"}, {["x"] = 1, ["y"] = 5, ["z"] = 3, ["name"] = "default:wood"}, {["x"] = 1, ["y"] = 5, ["z"] = 13, ["name"] = "default:wood"}, {["x"] = 1, ["y"] = 5, ["z"] = 14, ["name"] = "default:wood"}, {["x"] = 1, ["y"] = 6, ["z"] = 2, ["name"] = "default:wood"}, {["x"] = 1, ["y"] = 6, ["z"] = 3, ["name"] = "default:wood"}, {["x"] = 1, ["y"] = 6, ["z"] = 13, ["name"] = "default:wood"}, {["x"] = 1, ["y"] = 6, ["z"] = 14, ["name"] = "default:wood"}, {["x"] = 1, ["y"] = 7, ["z"] = 2, ["name"] = "default:wood"}, {["x"] = 1, ["y"] = 7, ["z"] = 3, ["name"] = "default:wood"}, {["x"] = 1, ["y"] = 7, ["z"] = 13, ["name"] = "default:wood"}, {["x"] = 1, ["y"] = 7, ["z"] = 14, ["name"] = "default:wood"}, {["x"] = 1, ["y"] = 8, ["z"] = 2, ["name"] = "default:wood"}, {["x"] = 1, ["y"] = 8, ["z"] = 3, ["name"] = "default:wood"}, {["x"] = 1, ["y"] = 8, ["z"] = 13, ["name"] = "default:wood"}, {["x"] = 1, ["y"] = 8, ["z"] = 14, ["name"] = "default:wood"}, {["x"] = 1, ["y"] = 9, ["z"] = 2, ["name"] = "default:wood"}, {["x"] = 1, ["y"] = 9, ["z"] = 3, ["name"] = "default:wood"}, {["x"] = 1, ["y"] = 9, ["z"] = 13, ["name"] = "default:wood"}, {["x"] = 1, ["y"] = 9, ["z"] = 14, ["name"] = "default:wood"}, {["x"] = 1, ["y"] = 10, ["z"] = 2, ["name"] = "default:wood"}, {["x"] = 1, ["y"] = 10, ["z"] = 3, ["name"] = "default:wood"}, {["x"] = 1, ["y"] = 10, ["z"] = 13, ["name"] = "default:wood"}, {["x"] = 1, ["y"] = 10, ["z"] = 14, ["name"] = "default:wood"}, {["x"] = 1, ["y"] = 11, ["z"] = 2, ["name"] = "default:wood"}, {["x"] = 1, ["y"] = 11, ["z"] = 3, ["name"] = "default:wood"}, {["x"] = 1, ["y"] = 11, ["z"] = 13, ["name"] = "default:wood"}, {["x"] = 1, ["y"] = 11, ["z"] = 14, ["name"] = "default:wood"}, {["x"] = 1, ["y"] = 12, ["z"] = 2, ["name"] = "default:wood"}, {["x"] = 1, ["y"] = 12, ["z"] = 3, ["name"] = "default:wood"}, {["x"] = 1, ["y"] = 12, ["z"] = 13, ["name"] = "default:wood"}, {["x"] = 1, ["y"] = 12, ["z"] = 14, ["name"] = "default:wood"}, {["x"] = 1, ["y"] = 13, ["z"] = 2, ["name"] = "default:wood"}, {["x"] = 1, ["y"] = 13, ["z"] = 3, ["name"] = "default:wood"}, {["x"] = 1, ["y"] = 13, ["z"] = 13, ["name"] = "default:wood"}, {["x"] = 1, ["y"] = 13, ["z"] = 14, ["name"] = "default:wood"}, {["x"] = 1, ["y"] = 14, ["z"] = 2, ["name"] = "default:wood"}, {["x"] = 1, ["y"] = 14, ["z"] = 3, ["name"] = "default:wood"}, {["x"] = 1, ["y"] = 14, ["z"] = 13, ["name"] = "default:wood"}, {["x"] = 1, ["y"] = 14, ["z"] = 14, ["name"] = "default:wood"}, {["x"] = 1, ["y"] = 15, ["z"] = 2, ["name"] = "default:wood"}, {["x"] = 1, ["y"] = 15, ["z"] = 3, ["name"] = "default:wood"}, {["x"] = 1, ["y"] = 15, ["z"] = 13, ["name"] = "default:wood"}, {["x"] = 1, ["y"] = 15, ["z"] = 14, ["name"] = "default:wood"}, {["x"] = 2, ["y"] = 0, ["z"] = 1, ["name"] = "default:wood"}, {["x"] = 2, ["y"] = 0, ["z"] = 2, ["name"] = "default:wood"}, {["x"] = 2, ["y"] = 0, ["z"] = 3, ["name"] = "default:wood"}, {["x"] = 2, ["y"] = 0, ["z"] = 4, ["name"] = "default:wood"}, {["x"] = 2, ["y"] = 0, ["z"] = 12, ["name"] = "default:wood"}, {["x"] = 2, ["y"] = 0, ["z"] = 13, ["name"] = "default:wood"}, {["x"] = 2, ["y"] = 0, ["z"] = 14, ["name"] = "default:wood"}, {["x"] = 2, ["y"] = 0, ["z"] = 15, ["name"] = "default:wood"}, {["x"] = 2, ["y"] = 1, ["z"] = 2, ["name"] = "default:wood"}, {["x"] = 2, ["y"] = 1, ["z"] = 3, ["name"] = "default:wood"}, {["x"] = 2, ["y"] = 1, ["z"] = 13, ["name"] = "default:wood"}, {["x"] = 2, ["y"] = 1, ["z"] = 14, ["name"] = "default:wood"}, {["x"] = 2, ["y"] = 2, ["z"] = 2, ["name"] = "default:wood"}, {["x"] = 2, ["y"] = 2, ["z"] = 3, ["name"] = "default:wood"}, {["x"] = 2, ["y"] = 2, ["z"] = 13, ["name"] = "default:wood"}, {["x"] = 2, ["y"] = 2, ["z"] = 14, ["name"] = "default:wood"}, {["x"] = 2, ["y"] = 3, ["z"] = 2, ["name"] = "default:wood"}, {["x"] = 2, ["y"] = 3, ["z"] = 3, ["name"] = "default:wood"}, {["x"] = 2, ["y"] = 3, ["z"] = 13, ["name"] = "default:wood"}, {["x"] = 2, ["y"] = 3, ["z"] = 14, ["name"] = "default:wood"}, {["x"] = 2, ["y"] = 4, ["z"] = 2, ["name"] = "default:wood"}, {["x"] = 2, ["y"] = 4, ["z"] = 3, ["name"] = "default:wood"}, {["x"] = 2, ["y"] = 4, ["z"] = 13, ["name"] = "default:wood"}, {["x"] = 2, ["y"] = 4, ["z"] = 14, ["name"] = "default:wood"}, {["x"] = 2, ["y"] = 5, ["z"] = 2, ["name"] = "default:wood"}, {["x"] = 2, ["y"] = 5, ["z"] = 3, ["name"] = "default:wood"}, {["x"] = 2, ["y"] = 5, ["z"] = 13, ["name"] = "default:wood"}, {["x"] = 2, ["y"] = 5, ["z"] = 14, ["name"] = "default:wood"}, {["x"] = 2, ["y"] = 6, ["z"] = 2, ["name"] = "default:wood"}, {["x"] = 2, ["y"] = 6, ["z"] = 3, ["name"] = "default:wood"}, {["x"] = 2, ["y"] = 6, ["z"] = 13, ["name"] = "default:wood"}, {["x"] = 2, ["y"] = 6, ["z"] = 14, ["name"] = "default:wood"}, {["x"] = 2, ["y"] = 7, ["z"] = 2, ["name"] = "default:wood"}, {["x"] = 2, ["y"] = 7, ["z"] = 3, ["name"] = "default:wood"}, {["x"] = 2, ["y"] = 7, ["z"] = 13, ["name"] = "default:wood"}, {["x"] = 2, ["y"] = 7, ["z"] = 14, ["name"] = "default:wood"}, {["x"] = 2, ["y"] = 8, ["z"] = 2, ["name"] = "default:wood"}, {["x"] = 2, ["y"] = 8, ["z"] = 3, ["name"] = "default:wood"}, {["x"] = 2, ["y"] = 8, ["z"] = 13, ["name"] = "default:wood"}, {["x"] = 2, ["y"] = 8, ["z"] = 14, ["name"] = "default:wood"}, {["x"] = 2, ["y"] = 9, ["z"] = 2, ["name"] = "default:wood"}, {["x"] = 2, ["y"] = 9, ["z"] = 3, ["name"] = "default:wood"}, {["x"] = 2, ["y"] = 9, ["z"] = 13, ["name"] = "default:wood"}, {["x"] = 2, ["y"] = 9, ["z"] = 14, ["name"] = "default:wood"}, {["x"] = 2, ["y"] = 10, ["z"] = 2, ["name"] = "default:wood"}, {["x"] = 2, ["y"] = 10, ["z"] = 3, ["name"] = "default:wood"}, {["x"] = 2, ["y"] = 10, ["z"] = 13, ["name"] = "default:wood"}, {["x"] = 2, ["y"] = 10, ["z"] = 14, ["name"] = "default:wood"}, {["x"] = 2, ["y"] = 11, ["z"] = 2, ["name"] = "default:wood"}, {["x"] = 2, ["y"] = 11, ["z"] = 3, ["name"] = "default:wood"}, {["x"] = 2, ["y"] = 11, ["z"] = 13, ["name"] = "default:wood"}, {["x"] = 2, ["y"] = 11, ["z"] = 14, ["name"] = "default:wood"}, {["x"] = 2, ["y"] = 12, ["z"] = 2, ["name"] = "default:wood"}, {["x"] = 2, ["y"] = 12, ["z"] = 3, ["name"] = "default:wood"}, {["x"] = 2, ["y"] = 12, ["z"] = 13, ["name"] = "default:wood"}, {["x"] = 2, ["y"] = 12, ["z"] = 14, ["name"] = "default:wood"}, {["x"] = 2, ["y"] = 13, ["z"] = 2, ["name"] = "default:wood"}, {["x"] = 2, ["y"] = 13, ["z"] = 3, ["name"] = "default:wood"}, {["x"] = 2, ["y"] = 13, ["z"] = 13, ["name"] = "default:wood"}, {["x"] = 2, ["y"] = 13, ["z"] = 14, ["name"] = "default:wood"}, {["x"] = 2, ["y"] = 14, ["z"] = 2, ["name"] = "default:wood"}, {["x"] = 2, ["y"] = 14, ["z"] = 3, ["name"] = "default:wood"}, {["x"] = 2, ["y"] = 14, ["z"] = 13, ["name"] = "default:wood"}, {["x"] = 2, ["y"] = 14, ["z"] = 14, ["name"] = "default:wood"}, {["x"] = 2, ["y"] = 15, ["z"] = 2, ["name"] = "default:wood"}, {["x"] = 2, ["y"] = 15, ["z"] = 3, ["name"] = "default:wood"}, {["x"] = 2, ["y"] = 15, ["z"] = 13, ["name"] = "default:wood"}, {["x"] = 2, ["y"] = 15, ["z"] = 14, ["name"] = "default:wood"}, {["x"] = 3, ["y"] = 0, ["z"] = 1, ["name"] = "default:wood"}, {["x"] = 3, ["y"] = 0, ["z"] = 2, ["name"] = "default:wood"}, {["x"] = 3, ["y"] = 0, ["z"] = 3, ["name"] = "default:wood"}, {["x"] = 3, ["y"] = 0, ["z"] = 4, ["name"] = "default:wood"}, {["x"] = 3, ["y"] = 0, ["z"] = 12, ["name"] = "default:wood"}, {["x"] = 3, ["y"] = 0, ["z"] = 13, ["name"] = "default:wood"}, {["x"] = 3, ["y"] = 0, ["z"] = 14, ["name"] = "default:wood"}, {["x"] = 3, ["y"] = 0, ["z"] = 15, ["name"] = "default:wood"}, {["x"] = 6, ["y"] = 0, ["z"] = 6, ["name"] = "default:wood"}, {["x"] = 6, ["y"] = 0, ["z"] = 7, ["name"] = "default:wood"}, {["x"] = 6, ["y"] = 0, ["z"] = 8, ["name"] = "default:wood"}, {["x"] = 6, ["y"] = 0, ["z"] = 9, ["name"] = "default:wood"}, {["x"] = 7, ["y"] = 0, ["z"] = 6, ["name"] = "default:wood"}, {["x"] = 7, ["y"] = 0, ["z"] = 7, ["name"] = "default:wood"}, {["x"] = 7, ["y"] = 0, ["z"] = 8, ["name"] = "default:wood"}, {["x"] = 7, ["y"] = 0, ["z"] = 9, ["name"] = "default:wood"}, {["x"] = 7, ["y"] = 1, ["z"] = 7, ["name"] = "default:wood"}, {["x"] = 7, ["y"] = 1, ["z"] = 8, ["name"] = "default:wood"}, {["x"] = 7, ["y"] = 2, ["z"] = 7, ["name"] = "default:wood"}, {["x"] = 7, ["y"] = 2, ["z"] = 8, ["name"] = "default:wood"}, {["x"] = 7, ["y"] = 3, ["z"] = 7, ["name"] = "default:wood"}, {["x"] = 7, ["y"] = 3, ["z"] = 8, ["name"] = "default:wood"}, {["x"] = 7, ["y"] = 4, ["z"] = 7, ["name"] = "default:wood"}, {["x"] = 7, ["y"] = 4, ["z"] = 8, ["name"] = "default:wood"}, {["x"] = 7, ["y"] = 5, ["z"] = 7, ["name"] = "default:wood"}, {["x"] = 7, ["y"] = 5, ["z"] = 8, ["name"] = "default:wood"}, {["x"] = 7, ["y"] = 6, ["z"] = 7, ["name"] = "default:wood"}, {["x"] = 7, ["y"] = 6, ["z"] = 8, ["name"] = "default:wood"}, {["x"] = 7, ["y"] = 7, ["z"] = 7, ["name"] = "default:wood"}, {["x"] = 7, ["y"] = 7, ["z"] = 8, ["name"] = "default:wood"}, {["x"] = 7, ["y"] = 8, ["z"] = 7, ["name"] = "default:wood"}, {["x"] = 7, ["y"] = 8, ["z"] = 8, ["name"] = "default:wood"}, {["x"] = 7, ["y"] = 9, ["z"] = 7, ["name"] = "default:wood"}, {["x"] = 7, ["y"] = 9, ["z"] = 8, ["name"] = "default:wood"}, {["x"] = 7, ["y"] = 10, ["z"] = 7, ["name"] = "default:wood"}, {["x"] = 7, ["y"] = 10, ["z"] = 8, ["name"] = "default:wood"}, {["x"] = 7, ["y"] = 11, ["z"] = 7, ["name"] = "default:wood"}, {["x"] = 7, ["y"] = 11, ["z"] = 8, ["name"] = "default:wood"}, {["x"] = 7, ["y"] = 12, ["z"] = 7, ["name"] = "default:wood"}, {["x"] = 7, ["y"] = 12, ["z"] = 8, ["name"] = "default:wood"}, {["x"] = 7, ["y"] = 13, ["z"] = 7, ["name"] = "default:wood"}, {["x"] = 7, ["y"] = 13, ["z"] = 8, ["name"] = "default:wood"}, {["x"] = 7, ["y"] = 14, ["z"] = 7, ["name"] = "default:wood"}, {["x"] = 7, ["y"] = 14, ["z"] = 8, ["name"] = "default:wood"}, {["x"] = 7, ["y"] = 15, ["z"] = 7, ["name"] = "default:wood"}, {["x"] = 7, ["y"] = 15, ["z"] = 8, ["name"] = "default:wood"}, {["x"] = 8, ["y"] = 0, ["z"] = 6, ["name"] = "default:wood"}, {["x"] = 8, ["y"] = 0, ["z"] = 7, ["name"] = "default:wood"}, {["x"] = 8, ["y"] = 0, ["z"] = 8, ["name"] = "default:wood"}, {["x"] = 8, ["y"] = 0, ["z"] = 9, ["name"] = "default:wood"}, {["x"] = 8, ["y"] = 1, ["z"] = 7, ["name"] = "default:wood"}, {["x"] = 8, ["y"] = 1, ["z"] = 8, ["name"] = "default:wood"}, {["x"] = 8, ["y"] = 2, ["z"] = 7, ["name"] = "default:wood"}, {["x"] = 8, ["y"] = 2, ["z"] = 8, ["name"] = "default:wood"}, {["x"] = 8, ["y"] = 3, ["z"] = 7, ["name"] = "default:wood"}, {["x"] = 8, ["y"] = 3, ["z"] = 8, ["name"] = "default:wood"}, {["x"] = 8, ["y"] = 4, ["z"] = 7, ["name"] = "default:wood"}, {["x"] = 8, ["y"] = 4, ["z"] = 8, ["name"] = "default:wood"}, {["x"] = 8, ["y"] = 5, ["z"] = 7, ["name"] = "default:wood"}, {["x"] = 8, ["y"] = 5, ["z"] = 8, ["name"] = "default:wood"}, {["x"] = 8, ["y"] = 6, ["z"] = 7, ["name"] = "default:wood"}, {["x"] = 8, ["y"] = 6, ["z"] = 8, ["name"] = "default:wood"}, {["x"] = 8, ["y"] = 7, ["z"] = 7, ["name"] = "default:wood"}, {["x"] = 8, ["y"] = 7, ["z"] = 8, ["name"] = "default:wood"}, {["x"] = 8, ["y"] = 8, ["z"] = 7, ["name"] = "default:wood"}, {["x"] = 8, ["y"] = 8, ["z"] = 8, ["name"] = "default:wood"}, {["x"] = 8, ["y"] = 9, ["z"] = 7, ["name"] = "default:wood"}, {["x"] = 8, ["y"] = 9, ["z"] = 8, ["name"] = "default:wood"}, {["x"] = 8, ["y"] = 10, ["z"] = 7, ["name"] = "default:wood"}, {["x"] = 8, ["y"] = 10, ["z"] = 8, ["name"] = "default:wood"}, {["x"] = 8, ["y"] = 11, ["z"] = 7, ["name"] = "default:wood"}, {["x"] = 8, ["y"] = 11, ["z"] = 8, ["name"] = "default:wood"}, {["x"] = 8, ["y"] = 12, ["z"] = 7, ["name"] = "default:wood"}, {["x"] = 8, ["y"] = 12, ["z"] = 8, ["name"] = "default:wood"}, {["x"] = 8, ["y"] = 13, ["z"] = 7, ["name"] = "default:wood"}, {["x"] = 8, ["y"] = 13, ["z"] = 8, ["name"] = "default:wood"}, {["x"] = 8, ["y"] = 14, ["z"] = 7, ["name"] = "default:wood"}, {["x"] = 8, ["y"] = 14, ["z"] = 8, ["name"] = "default:wood"}, {["x"] = 8, ["y"] = 15, ["z"] = 7, ["name"] = "default:wood"}, {["x"] = 8, ["y"] = 15, ["z"] = 8, ["name"] = "default:wood"}, {["x"] = 9, ["y"] = 0, ["z"] = 6, ["name"] = "default:wood"}, {["x"] = 9, ["y"] = 0, ["z"] = 7, ["name"] = "default:wood"}, {["x"] = 9, ["y"] = 0, ["z"] = 8, ["name"] = "default:wood"}, {["x"] = 9, ["y"] = 0, ["z"] = 9, ["name"] = "default:wood"}, {["x"] = 12, ["y"] = 0, ["z"] = 0, ["name"] = "default:wood"}, {["x"] = 12, ["y"] = 0, ["z"] = 1, ["name"] = "default:wood"}, {["x"] = 12, ["y"] = 0, ["z"] = 2, ["name"] = "default:wood"}, {["x"] = 12, ["y"] = 0, ["z"] = 3, ["name"] = "default:wood"}, {["x"] = 12, ["y"] = 0, ["z"] = 12, ["name"] = "default:wood"}, {["x"] = 12, ["y"] = 0, ["z"] = 13, ["name"] = "default:wood"}, {["x"] = 12, ["y"] = 0, ["z"] = 14, ["name"] = "default:wood"}, {["x"] = 12, ["y"] = 0, ["z"] = 15, ["name"] = "default:wood"}, {["x"] = 13, ["y"] = 0, ["z"] = 0, ["name"] = "default:wood"}, {["x"] = 13, ["y"] = 0, ["z"] = 1, ["name"] = "default:wood"}, {["x"] = 13, ["y"] = 0, ["z"] = 2, ["name"] = "default:wood"}, {["x"] = 13, ["y"] = 0, ["z"] = 3, ["name"] = "default:wood"}, {["x"] = 13, ["y"] = 0, ["z"] = 12, ["name"] = "default:wood"}, {["x"] = 13, ["y"] = 0, ["z"] = 13, ["name"] = "default:wood"}, {["x"] = 13, ["y"] = 0, ["z"] = 14, ["name"] = "default:wood"}, {["x"] = 13, ["y"] = 0, ["z"] = 15, ["name"] = "default:wood"}, {["x"] = 13, ["y"] = 1, ["z"] = 1, ["name"] = "default:wood"}, {["x"] = 13, ["y"] = 1, ["z"] = 2, ["name"] = "default:wood"}, {["x"] = 13, ["y"] = 1, ["z"] = 13, ["name"] = "default:wood"}, {["x"] = 13, ["y"] = 1, ["z"] = 14, ["name"] = "default:wood"}, {["x"] = 13, ["y"] = 2, ["z"] = 1, ["name"] = "default:wood"}, {["x"] = 13, ["y"] = 2, ["z"] = 2, ["name"] = "default:wood"}, {["x"] = 13, ["y"] = 2, ["z"] = 13, ["name"] = "default:wood"}, {["x"] = 13, ["y"] = 2, ["z"] = 14, ["name"] = "default:wood"}, {["x"] = 13, ["y"] = 3, ["z"] = 1, ["name"] = "default:wood"}, {["x"] = 13, ["y"] = 3, ["z"] = 2, ["name"] = "default:wood"}, {["x"] = 13, ["y"] = 3, ["z"] = 13, ["name"] = "default:wood"}, {["x"] = 13, ["y"] = 3, ["z"] = 14, ["name"] = "default:wood"}, {["x"] = 13, ["y"] = 4, ["z"] = 1, ["name"] = "default:wood"}, {["x"] = 13, ["y"] = 4, ["z"] = 2, ["name"] = "default:wood"}, {["x"] = 13, ["y"] = 4, ["z"] = 13, ["name"] = "default:wood"}, {["x"] = 13, ["y"] = 4, ["z"] = 14, ["name"] = "default:wood"}, {["x"] = 13, ["y"] = 5, ["z"] = 1, ["name"] = "default:wood"}, {["x"] = 13, ["y"] = 5, ["z"] = 2, ["name"] = "default:wood"}, {["x"] = 13, ["y"] = 5, ["z"] = 13, ["name"] = "default:wood"}, {["x"] = 13, ["y"] = 5, ["z"] = 14, ["name"] = "default:wood"}, {["x"] = 13, ["y"] = 6, ["z"] = 1, ["name"] = "default:wood"}, {["x"] = 13, ["y"] = 6, ["z"] = 2, ["name"] = "default:wood"}, {["x"] = 13, ["y"] = 6, ["z"] = 13, ["name"] = "default:wood"}, {["x"] = 13, ["y"] = 6, ["z"] = 14, ["name"] = "default:wood"}, {["x"] = 13, ["y"] = 7, ["z"] = 1, ["name"] = "default:wood"}, {["x"] = 13, ["y"] = 7, ["z"] = 2, ["name"] = "default:wood"}, {["x"] = 13, ["y"] = 7, ["z"] = 13, ["name"] = "default:wood"}, {["x"] = 13, ["y"] = 7, ["z"] = 14, ["name"] = "default:wood"}, {["x"] = 13, ["y"] = 8, ["z"] = 1, ["name"] = "default:wood"}, {["x"] = 13, ["y"] = 8, ["z"] = 2, ["name"] = "default:wood"}, {["x"] = 13, ["y"] = 8, ["z"] = 13, ["name"] = "default:wood"}, {["x"] = 13, ["y"] = 8, ["z"] = 14, ["name"] = "default:wood"}, {["x"] = 13, ["y"] = 9, ["z"] = 1, ["name"] = "default:wood"}, {["x"] = 13, ["y"] = 9, ["z"] = 2, ["name"] = "default:wood"}, {["x"] = 13, ["y"] = 9, ["z"] = 13, ["name"] = "default:wood"}, {["x"] = 13, ["y"] = 9, ["z"] = 14, ["name"] = "default:wood"}, {["x"] = 13, ["y"] = 10, ["z"] = 1, ["name"] = "default:wood"}, {["x"] = 13, ["y"] = 10, ["z"] = 2, ["name"] = "default:wood"}, {["x"] = 13, ["y"] = 10, ["z"] = 13, ["name"] = "default:wood"}, {["x"] = 13, ["y"] = 10, ["z"] = 14, ["name"] = "default:wood"}, {["x"] = 13, ["y"] = 11, ["z"] = 1, ["name"] = "default:wood"}, {["x"] = 13, ["y"] = 11, ["z"] = 2, ["name"] = "default:wood"}, {["x"] = 13, ["y"] = 11, ["z"] = 13, ["name"] = "default:wood"}, {["x"] = 13, ["y"] = 11, ["z"] = 14, ["name"] = "default:wood"}, {["x"] = 13, ["y"] = 12, ["z"] = 1, ["name"] = "default:wood"}, {["x"] = 13, ["y"] = 12, ["z"] = 2, ["name"] = "default:wood"}, {["x"] = 13, ["y"] = 12, ["z"] = 13, ["name"] = "default:wood"}, {["x"] = 13, ["y"] = 12, ["z"] = 14, ["name"] = "default:wood"}, {["x"] = 13, ["y"] = 13, ["z"] = 1, ["name"] = "default:wood"}, {["x"] = 13, ["y"] = 13, ["z"] = 2, ["name"] = "default:wood"}, {["x"] = 13, ["y"] = 13, ["z"] = 13, ["name"] = "default:wood"}, {["x"] = 13, ["y"] = 13, ["z"] = 14, ["name"] = "default:wood"}, {["x"] = 13, ["y"] = 14, ["z"] = 1, ["name"] = "default:wood"}, {["x"] = 13, ["y"] = 14, ["z"] = 2, ["name"] = "default:wood"}, {["x"] = 13, ["y"] = 14, ["z"] = 13, ["name"] = "default:wood"}, {["x"] = 13, ["y"] = 14, ["z"] = 14, ["name"] = "default:wood"}, {["x"] = 13, ["y"] = 15, ["z"] = 1, ["name"] = "default:wood"}, {["x"] = 13, ["y"] = 15, ["z"] = 2, ["name"] = "default:wood"}, {["x"] = 13, ["y"] = 15, ["z"] = 13, ["name"] = "default:wood"}, {["x"] = 13, ["y"] = 15, ["z"] = 14, ["name"] = "default:wood"}, {["x"] = 14, ["y"] = 0, ["z"] = 0, ["name"] = "default:wood"}, {["x"] = 14, ["y"] = 0, ["z"] = 1, ["name"] = "default:wood"}, {["x"] = 14, ["y"] = 0, ["z"] = 2, ["name"] = "default:wood"}, {["x"] = 14, ["y"] = 0, ["z"] = 3, ["name"] = "default:wood"}, {["x"] = 14, ["y"] = 0, ["z"] = 12, ["name"] = "default:wood"}, {["x"] = 14, ["y"] = 0, ["z"] = 13, ["name"] = "default:wood"}, {["x"] = 14, ["y"] = 0, ["z"] = 14, ["name"] = "default:wood"}, {["x"] = 14, ["y"] = 0, ["z"] = 15, ["name"] = "default:wood"}, {["x"] = 14, ["y"] = 1, ["z"] = 1, ["name"] = "default:wood"}, {["x"] = 14, ["y"] = 1, ["z"] = 2, ["name"] = "default:wood"}, {["x"] = 14, ["y"] = 1, ["z"] = 13, ["name"] = "default:wood"}, {["x"] = 14, ["y"] = 1, ["z"] = 14, ["name"] = "default:wood"}, {["x"] = 14, ["y"] = 2, ["z"] = 1, ["name"] = "default:wood"}, {["x"] = 14, ["y"] = 2, ["z"] = 2, ["name"] = "default:wood"}, {["x"] = 14, ["y"] = 2, ["z"] = 13, ["name"] = "default:wood"}, {["x"] = 14, ["y"] = 2, ["z"] = 14, ["name"] = "default:wood"}, {["x"] = 14, ["y"] = 3, ["z"] = 1, ["name"] = "default:wood"}, {["x"] = 14, ["y"] = 3, ["z"] = 2, ["name"] = "default:wood"}, {["x"] = 14, ["y"] = 3, ["z"] = 13, ["name"] = "default:wood"}, {["x"] = 14, ["y"] = 3, ["z"] = 14, ["name"] = "default:wood"}, {["x"] = 14, ["y"] = 4, ["z"] = 1, ["name"] = "default:wood"}, {["x"] = 14, ["y"] = 4, ["z"] = 2, ["name"] = "default:wood"}, {["x"] = 14, ["y"] = 4, ["z"] = 13, ["name"] = "default:wood"}, {["x"] = 14, ["y"] = 4, ["z"] = 14, ["name"] = "default:wood"}, {["x"] = 14, ["y"] = 5, ["z"] = 1, ["name"] = "default:wood"}, {["x"] = 14, ["y"] = 5, ["z"] = 2, ["name"] = "default:wood"}, {["x"] = 14, ["y"] = 5, ["z"] = 13, ["name"] = "default:wood"}, {["x"] = 14, ["y"] = 5, ["z"] = 14, ["name"] = "default:wood"}, {["x"] = 14, ["y"] = 6, ["z"] = 1, ["name"] = "default:wood"}, {["x"] = 14, ["y"] = 6, ["z"] = 2, ["name"] = "default:wood"}, {["x"] = 14, ["y"] = 6, ["z"] = 13, ["name"] = "default:wood"}, {["x"] = 14, ["y"] = 6, ["z"] = 14, ["name"] = "default:wood"}, {["x"] = 14, ["y"] = 7, ["z"] = 1, ["name"] = "default:wood"}, {["x"] = 14, ["y"] = 7, ["z"] = 2, ["name"] = "default:wood"}, {["x"] = 14, ["y"] = 7, ["z"] = 13, ["name"] = "default:wood"}, {["x"] = 14, ["y"] = 7, ["z"] = 14, ["name"] = "default:wood"}, {["x"] = 14, ["y"] = 8, ["z"] = 1, ["name"] = "default:wood"}, {["x"] = 14, ["y"] = 8, ["z"] = 2, ["name"] = "default:wood"}, {["x"] = 14, ["y"] = 8, ["z"] = 13, ["name"] = "default:wood"}, {["x"] = 14, ["y"] = 8, ["z"] = 14, ["name"] = "default:wood"}, {["x"] = 14, ["y"] = 9, ["z"] = 1, ["name"] = "default:wood"}, {["x"] = 14, ["y"] = 9, ["z"] = 2, ["name"] = "default:wood"}, {["x"] = 14, ["y"] = 9, ["z"] = 13, ["name"] = "default:wood"}, {["x"] = 14, ["y"] = 9, ["z"] = 14, ["name"] = "default:wood"}, {["x"] = 14, ["y"] = 10, ["z"] = 1, ["name"] = "default:wood"}, {["x"] = 14, ["y"] = 10, ["z"] = 2, ["name"] = "default:wood"}, {["x"] = 14, ["y"] = 10, ["z"] = 13, ["name"] = "default:wood"}, {["x"] = 14, ["y"] = 10, ["z"] = 14, ["name"] = "default:wood"}, {["x"] = 14, ["y"] = 11, ["z"] = 1, ["name"] = "default:wood"}, {["x"] = 14, ["y"] = 11, ["z"] = 2, ["name"] = "default:wood"}, {["x"] = 14, ["y"] = 11, ["z"] = 13, ["name"] = "default:wood"}, {["x"] = 14, ["y"] = 11, ["z"] = 14, ["name"] = "default:wood"}, {["x"] = 14, ["y"] = 12, ["z"] = 1, ["name"] = "default:wood"}, {["x"] = 14, ["y"] = 12, ["z"] = 2, ["name"] = "default:wood"}, {["x"] = 14, ["y"] = 12, ["z"] = 13, ["name"] = "default:wood"}, {["x"] = 14, ["y"] = 12, ["z"] = 14, ["name"] = "default:wood"}, {["x"] = 14, ["y"] = 13, ["z"] = 1, ["name"] = "default:wood"}, {["x"] = 14, ["y"] = 13, ["z"] = 2, ["name"] = "default:wood"}, {["x"] = 14, ["y"] = 13, ["z"] = 13, ["name"] = "default:wood"}, {["x"] = 14, ["y"] = 13, ["z"] = 14, ["name"] = "default:wood"}, {["x"] = 14, ["y"] = 14, ["z"] = 1, ["name"] = "default:wood"}, {["x"] = 14, ["y"] = 14, ["z"] = 2, ["name"] = "default:wood"}, {["x"] = 14, ["y"] = 14, ["z"] = 13, ["name"] = "default:wood"}, {["x"] = 14, ["y"] = 14, ["z"] = 14, ["name"] = "default:wood"}, {["x"] = 14, ["y"] = 15, ["z"] = 1, ["name"] = "default:wood"}, {["x"] = 14, ["y"] = 15, ["z"] = 2, ["name"] = "default:wood"}, {["x"] = 14, ["y"] = 15, ["z"] = 13, ["name"] = "default:wood"}, {["x"] = 14, ["y"] = 15, ["z"] = 14, ["name"] = "default:wood"}, {["x"] = 15, ["y"] = 0, ["z"] = 0, ["name"] = "default:wood"}, {["x"] = 15, ["y"] = 0, ["z"] = 1, ["name"] = "default:wood"}, {["x"] = 15, ["y"] = 0, ["z"] = 2, ["name"] = "default:wood"}, {["x"] = 15, ["y"] = 0, ["z"] = 3, ["name"] = "default:wood"}, {["x"] = 15, ["y"] = 0, ["z"] = 12, ["name"] = "default:wood"}, {["x"] = 15, ["y"] = 0, ["z"] = 13, ["name"] = "default:wood"}, {["x"] = 15, ["y"] = 0, ["z"] = 14, ["name"] = "default:wood"}, {["x"] = 15, ["y"] = 0, ["z"] = 15, ["name"] = "default:wood"}}